2019-05-10 19:34:45,793 ERROR: Exception on /index [POST] [in c:\users\jager\flask\microblog\myenv\lib\site-packages\flask\app.py:1761]
Traceback (most recent call last):
  File "c:\users\jager\flask\microblog\myenv\lib\site-packages\urllib3\connection.py", line 159, in _new_conn
    (self._dns_host, self.port), self.timeout, **extra_kw)
  File "c:\users\jager\flask\microblog\myenv\lib\site-packages\urllib3\util\connection.py", line 80, in create_connection
    raise err
  File "c:\users\jager\flask\microblog\myenv\lib\site-packages\urllib3\util\connection.py", line 70, in create_connection
    sock.connect(sa)
ConnectionRefusedError: [WinError 10061] No connection could be made because the target machine actively refused it

During handling of the above exception, another exception occurred:

Traceback (most recent call last):
  File "c:\users\jager\flask\microblog\myenv\lib\site-packages\elasticsearch\connection\http_urllib3.py", line 115, in perform_request
    response = self.pool.urlopen(method, url, body, retries=False, headers=self.headers, **kw)
  File "c:\users\jager\flask\microblog\myenv\lib\site-packages\urllib3\connectionpool.py", line 638, in urlopen
    _stacktrace=sys.exc_info()[2])
  File "c:\users\jager\flask\microblog\myenv\lib\site-packages\urllib3\util\retry.py", line 344, in increment
    raise six.reraise(type(error), error, _stacktrace)
  File "c:\users\jager\flask\microblog\myenv\lib\site-packages\urllib3\packages\six.py", line 686, in reraise
    raise value
  File "c:\users\jager\flask\microblog\myenv\lib\site-packages\urllib3\connectionpool.py", line 600, in urlopen
    chunked=chunked)
  File "c:\users\jager\flask\microblog\myenv\lib\site-packages\urllib3\connectionpool.py", line 354, in _make_request
    conn.request(method, url, **httplib_request_kw)
  File "C:\Users\Jager\AppData\Local\Programs\Python\Python37-32\lib\http\client.py", line 1229, in request
    self._send_request(method, url, body, headers, encode_chunked)
  File "C:\Users\Jager\AppData\Local\Programs\Python\Python37-32\lib\http\client.py", line 1275, in _send_request
    self.endheaders(body, encode_chunked=encode_chunked)
  File "C:\Users\Jager\AppData\Local\Programs\Python\Python37-32\lib\http\client.py", line 1224, in endheaders
    self._send_output(message_body, encode_chunked=encode_chunked)
  File "C:\Users\Jager\AppData\Local\Programs\Python\Python37-32\lib\http\client.py", line 1016, in _send_output
    self.send(msg)
  File "C:\Users\Jager\AppData\Local\Programs\Python\Python37-32\lib\http\client.py", line 956, in send
    self.connect()
  File "c:\users\jager\flask\microblog\myenv\lib\site-packages\urllib3\connection.py", line 181, in connect
    conn = self._new_conn()
  File "c:\users\jager\flask\microblog\myenv\lib\site-packages\urllib3\connection.py", line 168, in _new_conn
    self, "Failed to establish a new connection: %s" % e)
urllib3.exceptions.NewConnectionError: <urllib3.connection.HTTPConnection object at 0x064594F0>: Failed to establish a new connection: [WinError 10061] No connection could be made because the target machine actively refused it

During handling of the above exception, another exception occurred:

Traceback (most recent call last):
  File "c:\users\jager\flask\microblog\myenv\lib\site-packages\flask\app.py", line 2292, in wsgi_app
    response = self.full_dispatch_request()
  File "c:\users\jager\flask\microblog\myenv\lib\site-packages\flask\app.py", line 1815, in full_dispatch_request
    rv = self.handle_user_exception(e)
  File "c:\users\jager\flask\microblog\myenv\lib\site-packages\flask\app.py", line 1718, in handle_user_exception
    reraise(exc_type, exc_value, tb)
  File "c:\users\jager\flask\microblog\myenv\lib\site-packages\flask\_compat.py", line 35, in reraise
    raise value
  File "c:\users\jager\flask\microblog\myenv\lib\site-packages\flask\app.py", line 1813, in full_dispatch_request
    rv = self.dispatch_request()
  File "c:\users\jager\flask\microblog\myenv\lib\site-packages\flask\app.py", line 1799, in dispatch_request
    return self.view_functions[rule.endpoint](**req.view_args)
  File "c:\users\jager\flask\microblog\myenv\lib\site-packages\flask_login\utils.py", line 261, in decorated_view
    return func(*args, **kwargs)
  File "C:\Users\Jager\Flask\microblog\app\main\routes.py", line 35, in index
    db.session.commit()
  File "c:\users\jager\flask\microblog\myenv\lib\site-packages\sqlalchemy\orm\scoping.py", line 162, in do
    return getattr(self.registry(), name)(*args, **kwargs)
  File "c:\users\jager\flask\microblog\myenv\lib\site-packages\sqlalchemy\orm\session.py", line 1026, in commit
    self.transaction.commit()
  File "c:\users\jager\flask\microblog\myenv\lib\site-packages\sqlalchemy\orm\session.py", line 500, in commit
    self.session.dispatch.after_commit(self.session)
  File "c:\users\jager\flask\microblog\myenv\lib\site-packages\sqlalchemy\event\attr.py", line 259, in __call__
    fn(*args, **kw)
  File "C:\Users\Jager\Flask\microblog\app\models.py", line 36, in after_commit
    add_to_index(obj.__tablename__, obj)
  File "C:\Users\Jager\Flask\microblog\app\search.py", line 11, in add_to_index
    body=payload)
  File "c:\users\jager\flask\microblog\myenv\lib\site-packages\elasticsearch\client\utils.py", line 73, in _wrapped
    return func(*args, params=params, **kwargs)
  File "c:\users\jager\flask\microblog\myenv\lib\site-packages\elasticsearch\client\__init__.py", line 300, in index
    _make_path(index, doc_type, id), params=params, body=body)
  File "c:\users\jager\flask\microblog\myenv\lib\site-packages\elasticsearch\transport.py", line 312, in perform_request
    status, headers, data = connection.perform_request(method, url, params, body, ignore=ignore, timeout=timeout)
  File "c:\users\jager\flask\microblog\myenv\lib\site-packages\elasticsearch\connection\http_urllib3.py", line 124, in perform_request
    raise ConnectionError('N/A', str(e), e)
elasticsearch.exceptions.ConnectionError: ConnectionError(<urllib3.connection.HTTPConnection object at 0x064594F0>: Failed to establish a new connection: [WinError 10061] No connection could be made because the target machine actively refused it) caused by: NewConnectionError(<urllib3.connection.HTTPConnection object at 0x064594F0>: Failed to establish a new connection: [WinError 10061] No connection could be made because the target machine actively refused it)
